Workbook

Sheet Hymns by Season
A1: Season # | B1: Season | C1: Season (Arabic) | D1: Next Dates (on/after 2026-10-22) | E1: Service(s) | F1: Hymn Title | G1: Hymn Title (Arabic) | H1: Languages Available | I1: Text Languages | J1: Hazzat Notation Languages | K1: Formats | L1: Tune | M1: Hymn Type | N1: Variations / Also Known As | O1: Hymn ID | P1: Link | Q1: Source | R1: suscopts.org Recording
A2: 1 | B2: Annual | C2: سنوي | D2: Not date-specific | E2: Distribution | F2: Psalm 150 | G2: المزمور المائة والخمسون | H2: Coptic, English, Arabic | I2: Coptic, English, Arabic | J2: Coptic, English | K2: Text, Hazzat notation | L2: Annual | M2: Praxis Response; Psalm 150 | N2: Psalm 150 Short Verses | O2: psalm-150-annual | P2: Open on hazzat | Q2: hazzat.com + suscopts.org | R2: Play (mp3)
A3: 1 | B3: Annual | C3: سنوي | D3: Not date-specific | E3: Distribution | F3: The Bread of Life | G3: خبز الحياة (بي أويك) | H3: Coptic, English, Arabic | I3: Coptic, English, Arabic | J3: Coptic, English | K3: Text, Hazzat notation | L3: Annual | M3: Communion Hymn | N3: Piwik | O3: the-bread-of-life | P3: Open on hazzat | Q3: hazzat.com + suscopts.org | R3: Play (mp3)
A4: 1 | B4: Annual | C4: سنوي | D4: Not date-specific | E4: Distribution; Midnight Psalmody | F4: End of Service Hymn | G4: لحن ختام الخدمة | H4: Coptic, English, Arabic | I4: Coptic, English, Arabic | K4: Text | L4: Tawaf | M4: End of Service | O4: end-of-service-hymn-annual | P4: Open on hazzat | Q4: hazzat.com
A5: 1 | B5: Annual | C5: سنوي | D5: Not date-specific | E5: Liturgy of St. Basil | F5: Aspasmos Adam (Rejoice O Mary) | G5: أسبسمس آدام (إفرحي يا مريم) | H5: Coptic, English, Arabic | I5: Coptic, English, Arabic | J5: Coptic, English, Arabic | K5: Text, Hazzat notation, Vertical Hazzat | L5: Adam | M5: Aspasmos Adam | O5: aspasmos-adam-rejoice-o-mary | P5: Open on hazzat | Q5: hazzat.com + suscopts.org | R5: Play (mp3)
A6: 1 | B6: Annual | C6: سنوي | D6: Not date-specific | E6: Liturgy of St. Basil | F6: Greet One Another | G6: قبلوا بعضكم بعضاً | H6: Coptic, English | I6: Coptic, English | J6: Coptic | K6: Text, Hazzat notation | L6: Annual | M6: Unspecified | N6: Aspazeste (Greet One Another) | O6: greet-one-another | P6: Open on hazzat | Q6: hazzat.com
A7: 1 | B7: Annual | C7: سنوي | D7: Not date-specific | E7: Liturgy of St. Basil | F7: Aspasmos Watos (O Lord) | G7: أسبسمس واطس (أيها الرب) | H7: Coptic, English, Arabic | I7: Coptic, English, Arabic | J7: Coptic, English, Arabic | K7: Text, Hazzat notation, Vertical Hazzat, Musical notes | L7: Watos | M7: Aspasmos Watos | O7: aspasmos-watos-o-lord | P7: Open on hazzat | Q7: hazzat.com + suscopts.org | R7: Play (mp3)
A8: 1 | B8: Annual | C8: سنوي | D8: Not date-specific | E8: Liturgy of St. Basil | F8: Amen Amen Amen Ton Thanaton | G8: أمين أمين أمين طون ثاناطون | H8: None yet (listed on site, no content) | L8: Annual | M8: Unspecified | O8: amen-amen-amen-ton-thanaton | P8: Open on hazzat | Q8: hazzat.com + suscopts.org | R8: Play (mp3)
A9: 1 | B9: Annual | C9: سنوي | D9: Not date-specific | E9: Liturgy of St. Basil | F9: Penishti | G9: بينيشتي | H9: Coptic, English | I9: Coptic, English | J9: Coptic, English | K9: Text, Hazzat notation | L9: Annual | M9: Unspecified | O9: penishti | P9: Open on hazzat | Q9: hazzat.com
A10: 1 | B10: Annual | C10: سنوي | D10: Not date-specific | E10: Liturgy of St. Basil | F10: Penishti (Great) | G10: بينيشتي (الكبيرة) | H10: Coptic, English | I10: Coptic, English | K10: Text | L10: Annual | M10: Unspecified | O10: penishti-great | P10: Open on hazzat | Q10: hazzat.com + suscopts.org | R10: Play (mp3)
A11: 1 | B11: Annual | C11: سنوي | D11: Not date-specific | E11: Liturgy of St. Basil | F11: As it Was (Osberein) | G11: كما كان (أوس بيرين) | H11: None yet (listed on site, no content) | L11: Annual | M11: Unspecified | O11: as-it-was-osberein | P11: Open on hazzat | Q11: hazzat.com + suscopts.org | R11: Play (mp3)
A12: 1 | B12: Annual | C12: سنوي | D12: Not date-specific | E12: Liturgy of St. Basil | F12: One is the All Holy Father | G12: واحداً هو الآب القدوس | H12: None yet (listed on site, no content) | L12: Annual | M12: Unspecified | O12: one-is-the-all-holy-father | P12: Open on hazzat | Q12: hazzat.com
A13: 1 | B13: Annual | C13: سنوي | D13: Not date-specific | E13: Liturgy of St. Gregory | F13: Through the Intercessions | H13: None yet (listed on site, no content) | L13: Gregorian | M13: Unspecified | O13: through-the-intercessions | P13: Open on hazzat | Q13: hazzat.com
A14: 1 | B14: Annual | C14: سنوي | D14: Not date-specific | E14: Liturgy of St. Gregory | F14: According to Your Mercy (Kata to Eleos) | H14: Coptic, English, Arabic | I14: Coptic, English, Arabic | J14: Coptic | K14: Text, Hazzat notation | L14: Adam; Watos | M14: Aspasmos Adam; Aspasmos Watos | N14: Melismatic Ending | O14: according-to-your-mercy-kata-to-eleos-gregorian | P14: Open on hazzat | Q14: hazzat.com
A15: 1 | B15: Annual | C15: سنوي | D15: Not date-specific | E15: Liturgy of St. Gregory | F15: For Your People (Peklaos Ghar) | H15: Coptic, English, Arabic | I15: Coptic, English, Arabic | J15: Coptic | K15: Text, Hazzat notation | L15: Adam; Watos | M15: Aspasmos Adam; Aspasmos Watos | N15: Je Nai nan; Eleyson Emas | O15: for-your-people-peklaos-ghar | P15: Open on hazzat | Q15: hazzat.com
A16: 1 | B16: Annual | C16: سنوي | D16: Not date-specific | E16: Liturgy of St. Gregory | F16: Loose, Remit, and Forgive (Vol Evol) | H16: Coptic, English, Arabic | I16: Coptic, English, Arabic | J16: Coptic, English, Arabic | K16: Text, Hazzat notation | L16: Adam | M16: Aspasmos Adam | O16: loose-remit-and-forgive-vol-evol | P16: Open on hazzat | Q16: hazzat.com
A17: 1 | B17: Annual | C17: سنوي | D17: Not date-specific | E17: Liturgy of St. Gregory | F17: Response for Introduction to the Fraction | G17: مرد مقدمة القسمه | H17: Coptic, English, Arabic | I17: Coptic, English, Arabic | J17: Coptic | K17: Text, Hazzat notation | L17: Adam; Watos | M17: Aspasmos Adam; Aspasmos Watos | N17: Amen; Melismatic Amen | O17: gregorian-response-for-introduction-to-the-fraction | P17: Open on hazzat | Q17: hazzat.com
A18: 1 | B18: Annual | C18: سنوي | D18: Not date-specific | E18: Liturgy of the Word | F18: The Hymn of Blessing (Ten Ouosht) | G18: لحن البركة (تين أوؤوشت) | H18: Coptic, English, Arabic | I18: Coptic, English, Arabic | J18: Coptic, English | K18: Text, Hazzat notation | L18: Annual | M18: Unspecified | O18: the-hymn-of-blessing-ten-ouosht | P18: Open on hazzat | Q18: hazzat.com
A19: 1 | B19: Annual | C19: سنوي | D19: Not date-specific | E19: Liturgy of the Word | F19: Shere Maria | G19: شيرى ماريا | H19: Coptic, English, Arabic | I19: Coptic, English, Arabic | J19: Coptic, English | K19: Text, Hazzat notation | L19: Unspecified | M19: Unspecified | O19: shere-maria | P19: Open on hazzat | Q19: hazzat.com
A20: 1 | B20: Annual | C20: سنوي | D20: Not date-specific | E20: Liturgy of the Word | F20: Lord Have Mercy (Keriye Eleyson) | G20: يارب أرحم (كيرياليسون) | H20: None yet (listed on site, no content) | L20: Unspecified | M20: Unspecified | O20: lord-have-mercy-keriye-eleyson | P20: Open on hazzat | Q20: hazzat.com
A21: 1 | B21: Annual | C21: سنوي | D21: Not date-specific | E21: Liturgy of the Word | F21: Apinav Shopi | G21: ابيناف شوبي | H21: Coptic, English, Arabic | I21: Coptic, English, Arabic | J21: Coptic | K21: Text, Hazzat notation | L21: Unspecified | M21: Unspecified | O21: apinav-shopi | P21: Open on hazzat | Q21: hazzat.com
A22: 1 | B22: Annual | C22: سنوي | D22: Not date-specific | E22: Liturgy of the Word | F22: Pray for these Holy and Precious Gifts | G22: صلوا من أجل هذه القرابين المقدسة الكريمة | H22: Audio only | K22: Audio | L22: Annual | M22: Processional | O22: pray-for-these-holy-and-precious-gifts | P22: Open on hazzat | Q22: hazzat.com
A23: 1 | B23: Annual | C23: سنوي | D23: Not date-specific | E23: Liturgy of the Word | F23: Al El Qorban | G23: آل القربان | H23: Coptic | J23: Coptic | K23: Hazzat notation | L23: Annual | M23: Processional | O23: al-el-qorban | P23: Open on hazzat | Q23: hazzat.com
A24: 1 | B24: Annual | C24: سنوي | D24: Not date-specific | E24: Liturgy of the Word | F24: Procession of the Lamb (Alleluia Fai Pe Piehoou) | G24: تقديم الحمل (الليلويا فاي بيبي) | H24: Coptic | J24: Coptic | K24: Hazzat notation | L24: Annual | M24: Processional | N24: Alleluia Fai Pe Piehoou | O24: procession-of-the-lamb-alleluia-fai-pe-piehoou-annual | P24: Open on hazzat | Q24: hazzat.com
A25: 1 | B25: Annual | C25: سنوي | D25: Not date-specific | E25: Liturgy of the Word | F25: Doxa Patri | G25: ذوكصابتري | H25: None yet (listed on site, no content) | L25: Annual | M25: Unspecified | O25: doxa-patri | P25: Open on hazzat | Q25: hazzat.com
A26: 1 | B26: Annual | C26: سنوي | D26: Not date-specific | E26: Liturgy of the Word | F26: Saved Amen (Sotis) | G26: سوتيس | H26: Coptic, English, Arabic | I26: Coptic, English, Arabic | J26: Coptic, English | K26: Text, Hazzat notation | L26: Unspecified | M26: Unspecified | N26: Sotis | O26: sotis | P26: Open on hazzat | Q26: hazzat.com
A27: 1 | B27: Annual | C27: سنوي | D27: Not date-specific | E27: Liturgy of the Word | F27: The Hymn of the Censer (Tai Shouri) | G27: لحن المجمرة (طاي شوري) | H27: Coptic, English, Arabic | I27: Coptic, English, Arabic | J27: Coptic, English | K27: Text, Hazzat notation | L27: Annual | M27: Censer Hymn | O27: the-hymn-of-the-censer-tai-shouri-annual | P27: Open on hazzat | Q27: hazzat.com
A28: 1 | B28: Annual | C28: سنوي | D28: Not date-specific | E28: Liturgy of the Word | F28: Hymn of the Intercessions | G28: الهيتنيات | H28: Coptic, English, Arabic | I28: Coptic, English, Arabic | J28: Coptic, English | K28: Text, Hazzat notation | L28: Unspecified | M28: Intercession | N28: Melismatic; Grand Melismatic; Intercession Verses | O28: hymn-of-the-intercessions | P28: Open on hazzat | Q28: hazzat.com
A29: 1 | B29: Annual | C29: سنوي | D29: Not date-specific | E29: Liturgy of the Word | F29: Apetjeek Evol | G29: أبيتجيك إيفول | H29: Coptic, English | I29: Coptic, English | J29: Coptic, English | K29: Text, Hazzat notation | L29: Annual | M29: Unspecified | O29: apetjeek-evol | P29: Open on hazzat | Q29: hazzat.com
A30: 1 | B30: Annual | C30: سنوي | D30: Not date-specific | E30: Liturgy of the Word | F30: Acts Response | G30: مرد الإبركسيس (شيري نى ماريا) | H30: Coptic, English | I30: Coptic, English | J30: Coptic, English | K30: Text, Hazzat notation | L30: Annual | M30: Praxis Response | N30: Hail to You, O Mary (Shere Ne Maria); Melismatic | O30: praxis-response-annual | P30: Open on hazzat | Q30: hazzat.com
A31: 1 | B31: Annual | C31: سنوي | D31: Not date-specific | E31: Liturgy of the Word | F31: 2nd Praxis Response (Tote Alithos) | G31: مرد إبركسيس ثاني (توتى اليثوس) | H31: Coptic, English, Arabic | I31: Coptic, English, Arabic | J31: Coptic, English | K31: Text, Hazzat notation | L31: Unspecified | M31: Praxis Response | O31: 2nd-praxis-response-tote-alithos | P31: Open on hazzat | Q31: hazzat.com
A32: 1 | B32: Annual | C32: سنوي | D32: Not date-specific | E32: Liturgy of the Word | F32: Trisagion (Agios) | G32: لحن الثلاث تقديسات (أجيوس) | H32: Coptic, English, Arabic | I32: Coptic, English, Arabic | K32: Text | L32: Annual | M32: Trisagion Hymn | O32: trisagion-agios-annual | P32: Open on hazzat | Q32: hazzat.com
A33: 1 | B33: Annual | C33: سنوي | D33: Not date-specific | E33: Liturgy of the Word; Matins; Vespers | F33: Gospel Response | G33: مرد الإنجيل | H33: None yet (listed on site, no content) | L33: Annual | M33: Gospel Response | O33: gospel-response-annual | P33: Open on hazzat | Q33: hazzat.com
A34: 1 | B34: Annual | C34: سنوي | D34: Not date-specific | E34: Matins; Vespers | F34: Introduction to the Doxologies | H34: English | I34: English | J34: English | K34: Text, Hazzat notation | L34: Adam | M34: Aspasmos Adam | O34: intro-to-the-doxologies | P34: Open on hazzat | Q34: hazzat.com
A35: 1 | B35: Annual | C35: سنوي | D35: Not date-specific | E35: Matins | F35: Doxology for St. Mary | H35: None yet (listed on site, no content) | L35: Not listed | M35: Not listed | O35: doxology-for-st-mary | P35: Open on hazzat | Q35: hazzat.com
A36: 1 | B36: Annual | C36: سنوي | D36: Not date-specific | E36: Matins | F36: Litany for the Oblations | H36: Coptic, English, Arabic | I36: Coptic, English, Arabic | J36: Coptic | K36: Text, Hazzat notation | L36: Annual | M36: Deacon Response | O36: litany-for-the-oblations | P36: Open on hazzat | Q36: hazzat.com
A37: 1 | B37: Annual | C37: سنوي | D37: Not date-specific | E37: Matins Psalmody | F37: Morning Doxology | G37: ذكصولوجية باكر | H37: Coptic, English, Arabic | I37: Coptic, English, Arabic | K37: Text | L37: Annual | M37: Psalmody | N37: Hymn of the Seven Tunes | O37: morning-doxology-annual | P37: Open on hazzat | Q37: hazzat.com
A38: 1 | B38: Annual | C38: سنوي | D38: Not date-specific | E38: Matins Psalmody | F38: Morning Doxology: For Saint Mary | G38: ذكصولوجية باكر: لأجل السيدة العذراء | H38: Coptic, English, Arabic | I38: Coptic, English, Arabic | K38: Text | L38: Annual | M38: Psalmody | O38: morning-doxology-for-saint-mary-annual | P38: Open on hazzat | Q38: hazzat.com
A39: 1 | B39: Annual | C39: سنوي | D39: Not date-specific | E39: Matins Psalmody | F39: Morning Doxology: Also for Saint Mary | G39: ذكصولوجية باكر: وأيضاً لأجل السيدة العذراء | H39: Coptic, English, Arabic | I39: Coptic, English, Arabic | K39: Text | L39: Annual | M39: Psalmody | N39: Hymn of the Seven Tunes: Also for Saint Mary | O39: morning-doxology-also-for-saint-mary | P39: Open on hazzat | Q39: hazzat.com
A40: 1 | B40: Annual | C40: سنوي | D40: Not date-specific | E40: Matins Psalmody | F40: Morning Doxology: For the Angels | G40: ذكصولوجية باكر: لأجل الملائكة | H40: Coptic, English, Arabic | I40: Coptic, English, Arabic | K40: Text | L40: Annual | M40: Psalmody | N40: Hymn of the Seven Tunes: For the Angels | O40: morning-doxology-for-the-angels | P40: Open on hazzat | Q40: hazzat.com
...

Sheet Master Hymn List
A1: Hymn Title | B1: Hymn Title (Arabic) | C1: Languages Available | D1: Season(s) | E1: # Seasons | F1: Formats | G1: Tune | H1: Hymn Type | I1: Variations / Also Known As | J1: Hymn ID | K1: Source | L1: suscopts.org Recording
A2: 1st Canticle | B2: الهوس الأول | C2: Coptic, English, Arabic | D2: Annual; Bright Saturday | E2: 2 | F2: Text | G2: Unspecified | H2: Psalmody | J2: 1st-canticle | K2: hazzat.com
A3: 2nd Canticle | C3: Coptic, English, Arabic | D3: Annual | E3: 1 | F3: Text | G3: Unspecified | H3: Psalmody | J3: 2nd-canticle | K3: hazzat.com
A4: 2nd Praxis Response (Tote Alithos) | B4: مرد إبركسيس ثاني (توتى اليثوس) | C4: Coptic, English, Arabic | D4: Annual | E4: 1 | F4: Text, Hazzat notation | G4: Unspecified | H4: Praxis Response | J4: 2nd-praxis-response-tote-alithos | K4: hazzat.com
A5: 3rd Canticle | B5: الهوس الثالث | C5: Coptic, English, Arabic | D5: Annual; Kiahk; Bright Saturday; Saint Mary's Fast/Feast | E5: 4 | F5: Text, Hazzat notation, Vertical Hazzat, Musical notes | G5: Annual | H5: Psalmody | I5: Esmo Epchoise; Hos Erof; Arihoou Chasf; Eflogite | J5: 3rd-canticle-annual | K5: hazzat.com
A6: 4th Canticle | B6: الهوس الرابع | C6: Coptic, English, Arabic | D6: Annual; Saint Mary's Fast/Feast | E6: 2 | F6: Text | G6: Unspecified | H6: Psalmody | J6: 4th-canticle | K6: hazzat.com
A7: A Crown (O Ekloum) | C7: Coptic, English, Arabic | D7: Glorifications | E7: 1 | F7: Text, Hazzat notation | G7: Annual | H7: Glorification | I7: O Ekloum; A Crown for St. Philopater Mercurius; A Crown for St. Demiana; A Crown for St. George | J7: o-ekloum-a-crown | K7: hazzat.com
A8: A Proud Name (Ouran Enshoushou) | B8: أوران ان شوشو | C8: Coptic, English | D8: Epiphany | E8: 1 | F8: Text, Hazzat notation | G8: Unspecified | H8: Pre-Gospel | I8: Ouran Enshoushou; Long | J8: ouran-enshoushou | K8: hazzat.com
A9: According to Your Mercy (Kata to Eleos) | C9: Coptic, English, Arabic | D9: Annual | E9: 1 | F9: Text, Hazzat notation | G9: Adam; Watos | H9: Aspasmos Adam; Aspasmos Watos | I9: Melismatic Ending | J9: according-to-your-mercy-kata-to-eleos-gregorian | K9: hazzat.com
A10: Acts Response | B10: مرد الإبركسيس (شيري نى ماريا) | C10: Coptic, English | D10: Annual; Saint Mary's Fast/Feast | E10: 2 | F10: Text, Hazzat notation | G10: Annual | H10: Praxis Response | I10: Hail to You, O Mary (Shere Ne Maria); Melismatic | J10: praxis-response-annual | K10: hazzat.com
A11: Acts Response | B11: مرد الإبركسيس | C11: Coptic, English | D11: Nairouz | E11: 1 | F11: Text, Hazzat notation | G11: Unspecified | H11: Praxis Response | I11: Praxis Response | J11: praxis-response-nairouz | K11: hazzat.com
A12: Acts Response | C12: Coptic, English | D12: Feast of the Cross | E12: 1 | F12: Text, Hazzat notation | G12: Unspecified | H12: Praxis Response | I12: Praxis Response | J12: praxis-response-feast-of-the-cross | K12: hazzat.com
A13: Acts Response | B13: مرد الإبركسيس | C13: Coptic, English, Arabic | D13: Nativity | E13: 1 | F13: Text, Hazzat notation | G13: Annual | H13: Praxis Response | I13: Melismatic | J13: praxis-response-nativity | K13: hazzat.com
A14: Acts Response | B14: مرد الإبركسيس | C14: Coptic, English, Arabic | D14: Feast of Circumcision | E14: 1 | F14: Text, Hazzat notation | G14: Annual | H14: Praxis Response | J14: praxis-response-feast-of-circumcision | K14: hazzat.com
A15: Acts Response | B15: مرد الإبركسيس | C15: Coptic, English, Arabic | D15: Epiphany | E15: 1 | F15: Text, Hazzat notation | G15: Unspecified | H15: Praxis Response | J15: praxis-response-epiphany | K15: hazzat.com
A16: Acts Response | B16: مرد الإبركسيس | C16: English | D16: The Wedding at Cana of Galilee | E16: 1 | F16: Text, Hazzat notation | G16: Adam | H16: Aspasmos Adam | J16: praxis-response-the-wedding-at-cana-of-galilee | K16: hazzat.com
A17: Acts Response | B17: مرد الإبركسيس | C17: Coptic, English | D17: Great Lent - Saturdays & Sundays | E17: 1 | F17: Text, Hazzat notation | G17: Unspecified | H17: Praxis Response | I17: Praxis Response | J17: praxis-response-great-lent-saturdays-sundays | K17: hazzat.com
A18: Acts Response | B18: مرد الإبركسيس | C18: Coptic, English, Arabic | D18: Annunciation | E18: 1 | F18: Text, Hazzat notation | G18: Unspecified | H18: Praxis Response | I18: Praxis Response | J18: praxis-response-annunciation | K18: hazzat.com
A19: Acts Response | B19: مرد الإبركسيس | C19: Coptic, English, Arabic | D19: Lazarus Saturday | E19: 1 | F19: Text, Hazzat notation | G19: Unspecified | H19: Praxis Response | J19: praxis-response-lazarus-saturday | K19: hazzat.com
A20: Acts Response | B20: مرد الإبركسيس | C20: Coptic, English, Arabic | D20: The Lord's Entry into Jerusalem (Palm Sunday) | E20: 1 | F20: Text, Hazzat notation | G20: Unspecified | H20: Praxis Response | I20: Praxis Response | J20: praxis-response-the-lords-entry-into-jerusalem-palm-sunday | K20: hazzat.com
A21: Acts Response | C21: Coptic, English | D21: Bright Saturday | E21: 1 | F21: Text, Hazzat notation | G21: Unspecified | H21: Praxis Response | J21: praxis-response-bright-saturday | K21: hazzat.com
A22: Acts Response | C22: Coptic, English, Arabic | D22: Resurrection | E22: 1 | F22: Text, Hazzat notation | G22: Unspecified | H22: Praxis Response | I22: Melismatic | J22: praxis-response-resurrection | K22: hazzat.com
A23: Acts Response | C23: Coptic, English | D23: Ascension | E23: 1 | F23: Text, Hazzat notation | G23: Unspecified | H23: Praxis Response | J23: praxis-response-ascension | K23: hazzat.com
A24: Acts Response | C24: Coptic, English, Arabic | D24: Pentecost | E24: 1 | F24: Text, Hazzat notation | G24: Unspecified | H24: Praxis Response | J24: praxis-response-pentecost | K24: hazzat.com
A25: Acts Response | B25: مرد الإبركسيس | C25: Coptic, English | D25: Apostles Fast | E25: 1 | F25: Text, Hazzat notation | G25: Unspecified | H25: Praxis Response | J25: praxis-response-apostles-fast | K25: hazzat.com
A26: Acts Response | C26: Coptic, English | D26: Apostles Feast | E26: 1 | F26: Text | G26: Unspecified | H26: Praxis Response | I26: Praxis Response | J26: praxis-response-apostles-feast | K26: hazzat.com
A27: Acts Response | C27: English | D27: Transfiguration | E27: 1 | F27: Text, Hazzat notation | G27: Adam | H27: Aspasmos Adam | J27: acts-response-transfiguration | K27: hazzat.com
A28: Acts Response | C28: Coptic, English | D28: Papal | E28: 1 | F28: Text, Hazzat notation, Audio, Video | G28: Annual | H28: Praxis Response | I28: Praxis Response | J28: praxis-response-papal | K28: hazzat.com
A29: Acts Response (1st and 3rd Sunday) | C29: Coptic, English, Arabic | D29: Kiahk | E29: 1 | F29: Text, Hazzat notation, Vertical Hazzat | G29: Unspecified | H29: Praxis Response | I29: Praxis Response (1st and 3rd Sunday) | J29: praxis-response-1st-and-3rd-sunday | K29: hazzat.com
A30: Acts Response (2nd Sunday) | C30: Coptic, English | D30: Kiahk | E30: 1 | F30: Text, Hazzat notation, Vertical Hazzat | G30: Unspecified | H30: Praxis Response | I30: Praxis Response (2nd Sunday) | J30: praxis-response-2nd-sunday | K30: hazzat.com
A31: Acts Response (4th Sunday) | C31: Coptic, English | D31: Kiahk | E31: 1 | F31: Text, Hazzat notation, Vertical Hazzat | G31: Unspecified | H31: Praxis Response | I31: Praxis Response (4th Sunday) | J31: praxis-response-4th-sunday | K31: hazzat.com
A32: Acts Response (Share Efnouti) | B32: مرد الإبركسيس شارى إفنوتي | C32: Coptic, English | D32: Nineveh's Fast; Great Lent - Weekdays | E32: 2 | F32: Text, Hazzat notation | G32: Unspecified | H32: Praxis Response | I32: Praxis Response; Praxis Response (Share Efnouti) | J32: praxis-response-share-efnouti-great-lent-weekdays | K32: hazzat.com
A33: Adam Exposition | C33: Coptic, English | D33: Resurrection | E33: 1 | F33: Text, Hazzat notation | G33: Adam | H33: Aspasmos Adam | J33: adam-exposition | K33: hazzat.com
A34: Adam Psali | B34: إبصالية آدام | C34: Coptic, English | D34: Nairouz | E34: 1 | F34: Text | G34: Festal | H34: Adam Psali | J34: adam-psali-nairouz | K34: hazzat.com
A35: Adam Psali | B35: إبصالية آدام | C35: Coptic, English | D35: Pentecost | E35: 1 | F35: Text | G35: Festal | H35: Adam Psali | J35: adam-psali-pentecost | K35: hazzat.com
A36: Al El Qorban | B36: آل القربان | C36: Coptic | D36: Annual | E36: 1 | F36: Hazzat notation | G36: Annual | H36: Processional | J36: al-el-qorban | K36: hazzat.com
A37: All the Choirs (Kata ni Khoros) | C37: Coptic, English, Arabic | D37: Resurrection | E37: 1 | F37: Text, Hazzat notation | G37: Unspecified | H37: Unspecified | J37: all-the-choirs-kata-ni-khoros | K37: hazzat.com
A38: All the Choirs (Kata Nikhoros) Communion Hymn | C38: Coptic, English, Arabic | D38: Resurrection | E38: 1 | F38: Text, Hazzat notation | G38: Unspecified | H38: Communion Hymn | I38: All the Choirs (Kata Nikhoros) | J38: hymn-for-communion-kata-nikhoros | K38: hazzat.com
A39: All You Heavenly Orders | B39: يا كل الصفوف السمائية | C39: English, Arabic | D39: Resurrection; Pentecost | E39: 2 | F39: Text, Hazzat notation | G39: Unspecified | H39: Unspecified | J39: all-you-heavenly-orders | K39: hazzat.com
A40: All You Wise Men (Nisavev Teero) | C40: Coptic, English, Arabic | D40: Papal | E40: 1 | F40: Text, Hazzat notation, Vertical Hazzat, Audio, Video | G40: Unspecified | H40: Unspecified | I40: Nisavev Teero | J40: nisavev-teero | K40: hazzat.com
...

Sheet suscopts Cross-Reference
A1: suscopts.org Title | B1: Type | C1: Match on hazzat.com | D1: How They Compare | E1: Season | F1: suscopts.org Recording
A2: Altar Responses | B2: Hymn | C2: Not on hazzat.com (added as suscopts-only row) | D2: No hazzat equivalent. A collection of the people's/deacon's responses; hazzat lists some short responses separately (e.g. Lord Have Mercy, Through the Intercessions), but the recording's contents could not be checked. | E2: Annual | F2: Play (mp3)
A3: The Cherubim Worship You | B3: Hymn | C3: The Cherubim | D3: Same response under a different wording (Coptic 'Ni-Cheroubim'). hazzat lists it only under Coptic Weddings, worded 'The Cherubim worship Him'; suscopts gives it as 'worship You', as said in the Annual Liturgy. | E3: Annual | F3: Play (mp3)
A4: Amen Amen Amen | B4: Hymn | C4: Amen Amen Amen Ton Thanaton | D4: Same hymn; hazzat adds the Coptic incipit 'Ton Thanaton'. | E4: Annual | F4: Play (mp3)
A5: May Their Holy Blessings | B5: Hymn | C5: Penishti (Great) | D5: Probable match: suscopts uses the response's closing line; hazzat uses its Coptic opening word. hazzat's Penishti (Great) ends 'their holy blessings shall be with us. Amen.' and sits between Amen Amen Amen and As It Was, the same place as on suscopts. Not confirmed by listening. | E5: Annual | F5: Play (mp3)
A6: As It Was | B6: Hymn | C6: As it Was (Osberein) | D6: Same hymn; hazzat adds the Coptic incipit 'Osberein'. | E6: Annual | F6: Play (mp3)
A7: Introduction | B7: Liturgy segment (part of a full English liturgy recording) | C7: n/a (not a standalone hymn) | E7: Annual | F7: Play (mp3)
A8: Offeratory | B8: Liturgy segment (part of a full English liturgy recording) | C8: n/a (not a standalone hymn) | E8: Annual | F8: Play (mp3)
A9: The Readings | B9: Liturgy segment (part of a full English liturgy recording) | C9: n/a (not a standalone hymn) | E9: Annual | F9: Play (mp3)
A10: Upto the Prayer of Reconciliation | B10: Liturgy segment (part of a full English liturgy recording) | C10: n/a (not a standalone hymn) | E10: Annual | F10: Play (mp3)
A11: Aspasmos Adam (Rejoice O Mary) | B11: Hymn | C11: Aspasmos Adam (Rejoice O Mary) | D11: Same title. | E11: Annual | F11: Play (mp3)
A12: Upto the Aspasmos Vatos | B12: Liturgy segment (part of a full English liturgy recording) | C12: n/a (not a standalone hymn) | E12: Annual | F12: Play (mp3)
A13: Aspasmos Vatos (O Lord of Hosts) | B13: Hymn | C13: Aspasmos Watos (O Lord) | D13: Same hymn; spelling differs (Vatos / Watos) and hazzat shortens 'O Lord of Hosts' to 'O Lord'. | E13: Annual | F13: Play (mp3)
A14: Upto "Amen Amen Amen" | B14: Liturgy segment (part of a full English liturgy recording) | C14: n/a (not a standalone hymn) | E14: Annual | F14: Play (mp3)
A15: Upto "May Their Holy Blessings" | B15: Liturgy segment (part of a full English liturgy recording) | C15: n/a (not a standalone hymn) | E15: Annual | F15: Play (mp3)
A16: Upto Psalm 150 | B16: Liturgy segment (part of a full English liturgy recording) | C16: n/a (not a standalone hymn) | E16: Annual | F16: Play (mp3)
A17: Psalm 150 | B17: Hymn | C17: Psalm 150 | D17: Same title. | E17: Annual | F17: Play (mp3)
A18: Hymn: "The Bread of Life" (Pi-oik) | B18: Hymn | C18: The Bread of Life | D18: Same hymn; suscopts adds the Coptic incipit 'Pi-oik' (hazzat variation name: 'Piwik'). | E18: Annual | F18: Play (mp3)

Sheet Seasons
A1: Season # | B1: Season | C1: Season (Arabic) | D1: Next Dates (on/after 2026-10-22) | E1: Services | F1: Hymns
A2: 1 | B2: Annual | C2: سنوي | D2: Not date-specific | E2: Distribution; Liturgy of St. Basil; Liturgy of St. Gregory; Liturgy of the Word; Matins; Matins Psalmody; Midnight Psalmody; Vespers; Vespers Psalmody | F2: =COUNTIF('Hymns by Season'!$B$2:$B$607,B2) -> 64
A3: 2 | B3: Nairouz | C3: نيروز | D3: 2027-09-12 to 2027-09-27 | E3: Liturgy; Midnight Psalmody; Vespers & Matins | F3: =COUNTIF('Hymns by Season'!$B$2:$B$607,B3) -> 13
A4: 3 | B4: Feast of the Cross | C4: عيد الصليب | D4: 2027-03-19 | E4: Liturgy; Vespers & Matins | F4: =COUNTIF('Hymns by Season'!$B$2:$B$607,B4) -> 15
A5: 4 | B5: Kiahk | C5: كيهك | D5: 2026-11-25 to 2027-01-06 | E5: Liturgy; Midnight Psalmody; Vespers & Matins | F5: =COUNTIF('Hymns by Season'!$B$2:$B$607,B5) -> 40
A6: 5 | B6: Paramoune of Nativity | C6: برمون الميلاد | D6: 2027-01-06 | E6: Liturgy; Vespers & Matins | F6: =COUNTIF('Hymns by Season'!$B$2:$B$607,B6) -> 5
A7: 6 | B7: Nativity | C7: عيد الميلاد المجيد | D7: 2027-01-07 | E7: Liturgy; Matins | F7: =COUNTIF('Hymns by Season'!$B$2:$B$607,B7) -> 35
A8: 7 | B8: Feast of Circumcision | C8: عيد الختان | D8: 2027-01-14 | E8: Liturgy; Vespers & Matins | F8: =COUNTIF('Hymns by Season'!$B$2:$B$607,B8) -> 8
A9: 8 | B9: Paramoune of Epiphany | C9: برمون الغطاس | D9: 2027-01-18 | E9: Vespers | F9: =COUNTIF('Hymns by Season'!$B$2:$B$607,B9) -> 3
A10: 9 | B10: Epiphany | C10: عيد الغطاس | D10: 2027-01-19 | E10: Liturgy; Matins | F10: =COUNTIF('Hymns by Season'!$B$2:$B$607,B10) -> 28
A11: 10 | B11: The Wedding at Cana of Galilee | C11: عُرس قانا الجليل | D11: 2027-01-21 | E11: Liturgy | F11: =COUNTIF('Hymns by Season'!$B$2:$B$607,B11) -> 2
A12: 11 | B12: The Lord's Entry into the Temple | C12: دخول السيد المسيح الهيكل | D12: 2027-02-15 | E12: Liturgy; Vespers & Matins | F12: =COUNTIF('Hymns by Season'!$B$2:$B$607,B12) -> 8
A13: 12 | B13: Nineveh's Fast | C13: صوم أهل نينوى | D13: 2027-02-22 to 2027-02-24 | E13: Liturgy; Matins | F13: =COUNTIF('Hymns by Season'!$B$2:$B$607,B13) -> 18
... A35: 34 | B35: Reception of New Priest | C35: استقبال الكهنة | D35: Not date-specific | E35: Vespers | F35: =COUNTIF('Hymns by Season'!$B$2:$B$607,B35) -> 5
E36: Total hymn-season entries | F36: =SUM(F2:F35) -> 606
E37: Unique hymns | F37: =COUNTA('Master Hymn List'!A2:A465) -> 464

Sheet About
A1: Item | B1: Description
A2: Source | B2: hazzat.com: public content store used by the site (seasons, services, hymns, content), crawled 2026-10-22.
A3: Coverage | B3: All 34 seasons, 82 services, 464 unique hymns, 792 content items.
A4: Hymns by Season | B4: One row per hymn per season. A hymn sung in several seasons appears once in each.
A5: Master Hymn List | B5: One row per unique hymn, with every season it is listed under.
A6: Languages Available | B6: Languages with actual (non-empty) material on hazzat.com for that hymn: text columns, Hazzat notation, or video.
A7: Text Languages | B7: Languages present in the hymn's text (Coptic, English, Arabic columns).
A8: Hazzat Notation Languages | B8: Languages the Hazzat (melodic notation) is written over: Coptic, English and/or Arabic syllables.
A9: Next Dates | B9: Next date range on or after 2026-10-22 as published by hazzat.com; recurring services (Annual, Weddings, Funeral...) are not date-specific.
A10: suscopts.org | B10: suscopts.org's old hymn pages (deacons/hymns...) now redirect to the rebuilt deacons.suscopts.org, which no longer has a hymn library. Its only hymn material is the 'Some Hymn Recordings' list on the Deaconship page (17 audio tracks), cross-referenced on the 'suscopts Cross-Reference' sheet. Archived copies of the old pages (web.archive.org) could not be reached from this environment.
A11: Tune | B11: The melody the hymn is sung in (Annual, Festal, Kiahky, Great Lent, Shamy, Sha3anini, ...), from hazzat.com's documented API (api.hazzat.com/tunes), matched to each hymn by hazzat's own variation ids. 'Unspecified' is hazzat's own label. A hymn with two tunes lists both. 'Not listed' means the hymn is not in the API's tune lists.
A12: Hymn Type | B12: The kind of hymn (Psalmody, Doxology, Deacon Response, Praxis Response, Paralexis, ...), from api.hazzat.com/types, matched the same way.
... A14: Source | B14: hazzat.com, suscopts.org, or both. Rows marked suscopts.org only are hymns found on suscopts but not on hazzat.
